Workbook

Sheet Receptformat
B2: Namn | I2: Bild
C3: Falsk bearnaissås
B4: Kommentar
C5: Niiinis
B6: Antal portioner
C7: 2
B8: Huvudrecept
C9: Ingrediens | D9: Kvantitet | E9: Enhet | F9: Kommentar
C10: Crème fraiche | D10: 2 | E10: dl
C11: Buljongtärning - grönsak | D11: 1 | E11: st
C12: Ägg | D12: 2 | E12: st | F12: Gulor
C13: Dragon - torkad
B14: Delrecept
C15: Recept
C16: Falsk bearnaisås
B17: Receptkategorier
C18: Kategori
C19: Såser & Röror
B20: Länk
B22: Tillredning

Sheet Recept
A1: Receptnamn | B1: Källa | C1: Kommentar | D1: Portioner | E1: Länk | F1: Receptnamn | G1: Källa | H1: Kommentar | I1: Portioner | J1: Länk
A2: Beef rendang | D2: 2 | F2: Beef rendang | I2: 2
A3: Biye Barir | D3: 2 | F3: Biye Barir | I3: 2
A4: Bun | D4: 2 | F4: Bun | I4: 2
A5: Chicken curry with potato | D5: 2 | F5: Chicken curry with potato | I5: 2
A6: Chicken Madras | D6: 4 | F6: Chicken Madras | I6: 4
A7: Chicken Pakora | D7: 4 | F7: Chicken Pakora | I7: 4
A8: Chicken Tikka Masala | D8: 4 | F8: Chicken Tikka Masala | I8: 4
A9: Chicken Vindaloo | D9: 4 | F9: Chicken Vindaloo | I9: 4
A10: Chiliolja | D10: 4 | F10: Chilioil | I10: 4
A11: Chilli momo | D11: 2 | F11: Chilli momo | I11: 2
A12: Devilled chicken | D12: 2 | F12: Devilled chicken | I12: 2
A13: Dipping sauce for bun | D13: 2 | F13: Dipping sauce for bun | I13: 2
A14: Filipino pork barbecue | C14: Detta blir ca 6 grillspett | D14: 2 | F14: Filipino pork barbecue | H14: 6 skewers | I14: 2
A15: Fiskkakor | C15: Detta blir ca 7 rätt stora kakor | D15: 2 | F15: Fish cakes | H15: Approximately 7 quite big cakes | I15: 2
A16: Garam masala | C16: Detta blir drygt 1 dl färdig krydda | D16: 4 | F16: Garam masala | H16: Approximately 1 dl spice | I16: 4
A17: Green curry chicken | D17: 2 | F17: Green curry chicken | I17: 2
A18: Ingefärs- och sesamköttbullar | D18: 4 | F18: Ginger- and sesame meatballs | I18: 4
A19: Korokke (Japanska kroketter) | D19: 4 | F19: Korokke (Japanska kroketter) | I19: 4
A20: Kyckling med cashewnötter | D20: 2 | F20: Chicken with cashewnuts | I20: 2
A21: Laab | D21: 2 | F21: Laab | I21: 2
A22: Marinad till chicken with potato | D22: 2 | F22: Marinade to chicken with potato | I22: 2
A23: Murgh kadhai | D23: 2 | F23: Murgh kadhai | I23: 2
A24: Myntasås (raita) | D24: 4 | F24: Mint sauce (raita) | I24: 4
A25: Nudlar med kryddig lammfärs | D25: 2 | F25: Noodles with spicy minced lamb | I25: 2
A26: Nuoc Cham (Dipping sauce till papayasallad) | D26: 2 | F26: Nuoc Cham (Dipping sauce to papaya salad) | I26: 2
A27: Pad Kra Pao | D27: 2 | F27: Pad Kra Pao | I27: 2
A28: Red curry chicken | D28: 2 | F28: Red curry chicken | I28: 2
A29: Roti | D29: 2 | F29: Roti | I29: 2
A30: Räkspett | C30: Detta blir 4 spett | D30: 2 | F30: Shrimp skewer | H30: 4 skewers | I30: 2
A31: Sataysås | D31: 2 | F31: Sataysauce | I31: 2
A32: Sesamnudlar med honungskyckling | D32: 2 | F32: Sesamnudlar med honungskyckling | I32: 2
A33: Spicy asian kycklingspett | C33: Detta blir ca 6 - 7 spett | D33: 2 | F33: Spicy asian chicken skewer | H33: 6 - 7 skewers | I33: 2
A34: Strimlad biff | D34: 2 | F34: Shredded beef | I34: 2
A35: Tom Yam | D35: 2 | F35: Tom Yam | I35: 2
A36: Wokade grönsaker med strimlat kött | D36: 2 | F36: Stir fried vegetables with shredded beef | I36: 2
A37: Wontondumplings | C37: Detta blir ca 50 st dumplingar | D37: 4 | F37: Wontondumplings | H37: Approx. 50 st dumplings | I37: 4
A38: Yakitori (kycklingspett) | C38: Detta blir ca 6 - 7 spett | D38: 2 | F38: Yakitori (chicken skewers) | H38: 6 - 7 skewers | I38: 2
A39: Yakitorisås | D39: 2 | F39: Yakitori sauce | I39: 2
A40: Bröd med fårost | D40: 2 | F40: Bread with cheep cheese | I40: 2
...

Sheet Receptingredienser
A1: Receptnamn | B1: Sekvens | C1: Ingrediens | D1: Kvantitet | E1: Enhet | F1: Kommentar | G1: Receptdel
A2: Beef rendang | B2: 1 | C2: Lök - schalotten | D2: 3 | E2: st
A3: Beef rendang | B3: 2 | C3: Galangal | D3: 1 | E3: cm
A4: Beef rendang | B4: 3 | C4: Citrongräs | D4: 3 | E4: st
A5: Beef rendang | B5: 4 | C5: Vitlök | D5: 4 | E5: klyftor
A6: Beef rendang | B6: 5 | C6: Ingefärsrot | D6: 2 | E6: tsk
A7: Beef rendang | B7: 6 | C7: Chili - frukter (torkad) | D7: 10 | E7: st
A8: Beef rendang | B8: 7 | C8: Nötkött | D8: 800 | E8: g | F8: Rib eye, scotch
A9: Beef rendang | B9: 8 | C9: Kanel - stång | D9: 1 | E9: st
A10: Beef rendang | B10: 9 | C10: Kryddnejlika - hel | D10: 2 | E10: st
A11: Beef rendang | B11: 10 | C11: Stjärnanis | D11: 2 | E11: st
A12: Beef rendang | B12: 11 | C12: Kardemumma - kapslar | D12: 2 | E12: msk
A13: Beef rendang | B13: 12 | C13: Kokoskräm | D13: 2 | E13: dl
A14: Beef rendang | B14: 13 | C14: Vatten | D14: 2 | E14: dl
A15: Beef rendang | B15: 14 | C15: Tamarind | D15: 1 | E15: tsk
A16: Beef rendang | B16: 15 | C16: kaffirlimeblad | D16: 3 | E16: st | F16: Finhackade
A17: Beef rendang | B17: 16 | C17: Kokosflarn | D17: 3 | E17: msk
A18: Beef rendang | B18: 17 | C18: Socker - palm | D18: 0.5 | E18: msk
A19: Beef rendang | B19: 18 | C19: Salt
A20: Biye Barir | B20: 1 | C20: Gurkmeja | D20: 4 | E20: tsk
A21: Biye Barir | B21: 2 | C21: Salt | D21: 4 | E21: tsk
A22: Biye Barir | B22: 3 | C22: Olja - mat | D22: 3.5 | E22: dl
A23: Biye Barir | B23: 4 | C23: Smör | D23: 1 | E23: msk
A24: Biye Barir | B24: 5 | C24: Kanel - stång | D24: 1 | E24: st
A25: Biye Barir | B25: 6 | C25: Kryddnejlika - hel | D25: 2 | E25: st
A26: Biye Barir | B26: 7 | C26: Kardemumma - kapslar | D26: 2 | E26: st
A27: Biye Barir | B27: 8 | C27: Lök - gul | D27: 1 | E27: st | F27: Hackad, inte för fint
A28: Biye Barir | B28: 9 | C28: Ingefärspasta | D28: 1.5 | E28: msk
A29: Biye Barir | B29: 10 | C29: Vitlökspasta | D29: 1.5 | E29: msk
A30: Biye Barir | B30: 11 | C30: Chili - pulver | D30: 1 | E30: msk
A31: Biye Barir | B31: 12 | C31: Spiskummin | D31: 2 | E31: msk
A32: Biye Barir | B32: 13 | C32: Garam masala | D32: 3 | E32: msk
A33: Biye Barir | B33: 14 | C33: Vatten | D33: 5 | E33: dl
A34: Biye Barir | B34: 15 | C34: Socker - strö | D34: 1 | E34: tsk
A35: Biye Barir | B35: 16 | C35: Lök - torkad | D35: 2 | E35: dl
A36: Biye Barir | B36: 17 | C36: Chili - grön | D36: 3 | E36: st
A37: Biye Barir | B37: 18 | C37: Chili - röd | D37: 3 | E37: st
A38: Biye Barir | B38: 19 | C38: Matlagningsyoghurt | D38: 1.5 | E38: dl
A39: Biye Barir | B39: 20 | C39: Russin | D39: 0.5 | E39: dl
... A43: Bun | B43: 2 | C43: Nudlar - ris | D43: 100 | E43: g
...

Sheet Receptkategorisering
A1: Receptnamn | B1: Paj
A2: Ädelostcrostini (fast på kavring) | B2: Förrätter
A3: Ädelostcrostini (fast på kavring) | B3: Lunch
A4: Ädelostcrostini (fast på kavring) | B4: Snacks
A5: Adobo seasoning | B5: Kryddor
A6: Äggmuffins | B6: Lunch
A7: Aioli | B7: Såser & Röror
A8: Albondigas | B8: Köttfärs
A9: Albondigas | B9: Tapas
A10: Ångad kyckling från Bahamas | B10: Kyckling
A11: Baba ganush | B11: Såser & Röror
A12: Baharat | B12: Kryddor
... A584: Fänkål- and sellerisoppa | B584: Soppa

Sheet Delrecept
A1: Receptnamn | B1: Sekvens | C1: Delreceptnamn
A2: Bla bla | B2: 1 | C2: Niinis mumsiga sås
A3: Bun | B3: 1 | C3: Dipping sauce for bun
A4: Chicken curry with potato | B4: 1 | C4: Marinad till chicken curry with potato
A5: Chicken Pakora | B5: 1 | C5: Myntasås (raita)
A6: Chicken Tikka Masala | B6: 1 | C6: Roti
A7: Chicken Vindaloo | B7: 1 | C7: Roti
A8: Wontondumplings | B8: 1 | C8: Chiliolja
A9: Chilli momo | B9: 1 | C9: Wontondumplings
A10: Filipino pork barbecue | B10: 1 | C10: Marinad till filipino pork barbecue
A11: Fiskkakor | B11: 1 | C11: Jordnöts- och limesås
A12: Ingefärs- och sesamköttbullar | B12: 1 | C12: Sesamsås till Ingefärs- och sesamköttbullar
A13: Sesamnudlar med honungskyckling | B13: 1 | C13: Marinad till Sesamnudlar med honungskyckling
... A88: Bbq-kycklingsallad | B88: 2 | C88: Picklad rödlök

Sheet Tillredning
A1: Receptnamn | B1: Sekvens | C1: Åtgärd
A2: Bla bla | B2: 1 | C2: Borsta
A3: Bla bla | B3: 2 | C3: Skala
A4: Beef rendang | B4: 1 | C4: Blötlägg chilin i ca 2 timmar och ta sen ur fröna
A5: Beef rendang | B5: 2 | C5: Mixa lök, 2 citrongräs, vitlök, ingefära och chili till en pasta
A6: Beef rendang | B6: 3 | C6: Hetta upp olja I stekpannannan och tillsätt kryddpastan, kanel, kryddnejlika, stjärnanis och kardemumman tills det doftar, typ några minuter
A7: Beef rendang | B7: 4 | C7: Tillsätt köttet och den sparade citrongräset och stek I en minut
A8: Beef rendang | B8: 5 | C8: Tillsätt kokoskräm, tamarind och vatten och koka tills köttet är nästan klart
A9: Beef rendang | B9: 6 | C9: Woka kokosflarnen I en torr wok panna tills de är gyllenbruna (kerisik)
A10: Beef rendang | B10: 7 | C10: Tillsätt finhackade keffirlimeblad, kerisik, palmsocker och blanda väl
A11: Beef rendang | B11: 8 | C11: Sänk värmen, sätt på ett lock och låt småkoka I 1 - 1,5 timmar
A12: Biye Barir | B12: 1 | C12: Stycka, snitta och gnid in kycklingen I salt och gurkmeja
A13: Biye Barir | B13: 2 | C13: Hetta upp olja I woken och lägg I kanelstången, kardemummakapslarna och kryddnejlikan och fritera kycklingen så att den blir gyllenbrun. Inte för länge. Sätt åt sidan.
... A1105: Korean steak salad | B1105: 1 | C1105: Blanda alla ingredienserna till marinaden och lägg I köttet. Låt stå I rumstemperatur medan du förbereder dressingen och grönsakerna
A1106: Korean steak salad | C1106: Rör samman ingredienserna till dressingen
A1107: Korean steak salad | C1107: Skiva lök tunt, dela tomater, strimla gurka, strimla rättika tunt med mandolin och blanda allt med salladen
A1108: Korean steak salad | C1108: Låt köttet rinna av och stek sen på hög värme och skär I tunna skivor
A1109: Korean steak salad | C1109: Lägg alla grönsakerna på ett stort fat, lägg köttet överst och ringla över dressingen. Strössla över sesamfrön och pumpakärnor
A1110: Pepparbiff med fransk senapsås | B1110: 1 | C1110: Sätt ugnen på 150°.
A1111: Pepparbiff med fransk senapsås | B1111: 2 | C1111: Blanda tomaterna med olja och krydda med salt och peppar. Baka i ugnen i 30 minuter.
A1112: Pepparbiff med fransk senapsås | B1112: 3 | C1112: Forma 4 biffar av färsen. Krossa pepparkornen i mortel. Krydda biffarna runt om med salt och pepparkross.
A1113: Pepparbiff med fransk senapsås | B1113: 4 | C1113: Bryn biffarna i smör i stekpanna, stek klart på medelvärme i ca 5 minuter per sida. Flambera eventuellt i konjak. Ta upp biffarna och håll dem varma.
A1114: Pepparbiff med fransk senapsås | B1114: 5 | C1114: Skala och hacka löken och fräs den i pannan. Späd med fond, vatten och grädde, koka upp. Rör i senap, smaka av med salt.
A1115: Pepparbiff med fransk senapsås | B1115: 6 | C1115: Lägg biffarna i såsen och koka ett par minuter. Lägg i tomaterna. Servera med klyftpotatis och picklad gurka.
A1116: Sötsyrlig nudelwok med heta ingefärsräkor | B1116: 1 | C1116: Hetta upp oljan I en kastrull tills den nästan ryker. Lägg I pressad vitlök, ingerfära, chiliflakes, paprikapulver och en nypa salt. Rör run t och lägg sen I räkorna ett par minuter tills dom är rosa och klara. Sätt åt sidan.
A1117: Sötsyrlig nudelwok med heta ingefärsräkor | B1117: 2 | C1117: Woksås: Blanda oystersås, chilisås, lime juice och fisksås.
A1118: Sötsyrlig nudelwok med heta ingefärsräkor | B1118: 3 | C1118: Koka nudlarna enligt beskrivning på förpackningen. Skölj i iskallt vatten och låt rinna av ordentligt.
A1119: Sötsyrlig nudelwok med heta ingefärsräkor | B1119: 4 | C1119: Hetta upp en wok till rykande het. Häll I nån matsked olja och lägg I en hafckad vitlök, purjolök, gurka och paprika. Låt fräsa på hög värme tills det fått lite färg.
A1120: Sötsyrlig nudelwok med heta ingefärsräkor | B1120: 5 | C1120: Tillsätt nudlar, sockerrärter och woksåsen. Vänd runt och låt allt fräsa I någon minut
A1121: Sötsyrlig nudelwok med heta ingefärsräkor | B1121: 6 | C1121: Vänd upp på två tallrikar och toppa med räkorna och den färska koriandern
... A1290: Himmelskt god röra med kallrökt lax och räkor | B1290: 3 | C1290: Servera I baguette eller ugnsbakad potatis.
A1291: Bulgogilax
A1292: Ugnsrostad bulgogikyckling med klyftpotatis och chilimajonnäs
A1293: Spaghetti alla carbonara
A1294: Korv Stroganoff | B1294: 1 | C1294: Skär korven i strimlor och stek den i olja tills den börjat få färg
A1295: Korv Stroganoff | B1295: 2 | C1295: Tillsätt löken och fräs tills den mjuknat
A1296: Korv Stroganoff | B1296: 3 | C1296: Tillsätt tomatpurén och blanda runt
A1297: Korv Stroganoff | B1297: 4 | C1297: I med grädden, senapen och den pressade vitlöken
A1298: Korv Stroganoff | B1298: 5 | C1298: Salta och peppra och låt puttra tills grädden tjocknat lite
A1299: Korv Stroganoff | B1299: 6 | C1299: Servera med ris
...

Sheet Ingredienser
A1: Ädelost | B1: g | C1: Blue cheese | D1: g | E1: =MATCH(A1,Kalorilista!A:A,0) -> #N/A
A2: Ägg | B2: st | C2: Egg | D2: pc | E2: =MATCH(A2,Kalorilista!A:A,0) -> 266
A3: Ajvar relish | B3: tsk | C3: Ajvar relish | D3: tsp | E3: =MATCH(A3,Kalorilista!A:A,0) -> #N/A
A4: Anjovisfilé | B4: g | C4: Swedish anchovies fillet | D4: g | E4: =MATCH(A4,Kalorilista!A:A,0) -> #N/A
A5: Anjovisspad | B5: msk | C5: Swedish anchovy brine | D5: tbsp | E5: =MATCH(A5,Kalorilista!A:A,0) -> #N/A
A6: Apelsin | B6: st | C6: Orange | D6: pc | E6: =MATCH(A6,Kalorilista!A:A,0) -> 106
A7: Apelsinjuice | B7: dl | C7: Orange juice | D7: dl | E7: =MATCH(A7,Kalorilista!A:A,0) -> 109
A8: Äpple | B8: st | C8: Apple | D8: pc | E8: =MATCH(A8,Kalorilista!A:A,0) -> 127
A9: Äpplejuice | B9: dl | C9: Apple juice | D9: dl | E9: =MATCH(A9,Kalorilista!A:A,0) -> #N/A
A10: Ättika | B10: dl | C10: Vinegar | D10: dl | E10: =MATCH(A10,Kalorilista!A:A,0) -> #N/A
A11: Aubergine | B11: st | C11: Aubergine | D11: pc | E11: =MATCH(A11,Kalorilista!A:A,0) -> 34
A12: Avocado | B12: st | C12: Avocado | D12: pc | E12: =MATCH(A12,Kalorilista!A:A,0) -> #N/A
... A60: Citronsaft | B60: tsk | C60: Lemon juice | D60: tsp | E60: =MATCH(A60,Kalorilista!A:A,0) -> #N/A
A61: Citronzest | B61: tsk | C61: Lemon zest | E61: =MATCH(A61,Kalorilista!A:A,0) -> #N/A
A62: Cognac | B62: msk | C62: Cognac | D62: tbsp | E62: =MATCH(A62,Kalorilista!A:A,0) -> #N/A
A63: Couscous | B63: dl | C63: Couscous | D63: dl | E63: =MATCH(A63,Kalorilista!A:A,0) -> 426
A64: Crème fraiche | B64: g | C64: Crème fraiche | D64: g | E64: =MATCH(A64,Kalorilista!A:A,0) -> #N/A
A65: Creolekrydda | B65: tsk | C65: Creole spice | D65: tsp | E65: =MATCH(A65,Kalorilista!A:A,0) -> #N/A
A66: Curry | B66: tsk | C66: Curry spice | D66: tsp | E66: =MATCH(A66,Kalorilista!A:A,0) -> #N/A
A67: Curryblad | B67: st | C67: Curry leaf | D67: pc | E67: =MATCH(A67,Kalorilista!A:A,0) -> #N/A
A68: Currypasta - grön | B68: g | C68: Curry paste - green | D68: g | E68: =MATCH(A68,Kalorilista!A:A,0) -> #N/A
A69: Currypasta - gul | B69: g | C69: Curry paste - yellow | D69: g | E69: =MATCH(A69,Kalorilista!A:A,0) -> #N/A
A70: Currypasta - röd | B70: g | C70: Curry paste - red | D70: g | E70: =MATCH(A70,Kalorilista!A:A,0) -> #N/A
A71: Digestivekex | B71: st | C71: Digestive biscuit | D71: pc | E71: =MATCH(A71,Kalorilista!A:A,0) -> 468
A72: Dijonsenap | B72: tsk | C72: Dijon mustard | D72: tsp | E72: =MATCH(A72,Kalorilista!A:A,0) -> #N/A
A73: Dill | B73: knippe | C73: Dill | D73: bunch | E73: =MATCH(A73,Kalorilista!A:A,0) -> 128
... A172: Kyckling - bröstinnerfilé | B172: g | C172: Chicken - tenderloin | D172: g | E172: =MATCH(A172,Kalorilista!A:A,0) -> #N/A
A173: Kyckling - lår | B173: st | C173: Chicken - thighs | D173: pc
A174: Kyckling - hel | B174: g | C174: Chicken - hole | D174: g | E174: =MATCH(A174,Kalorilista!A:A,0) -> #N/A
A175: Kycklingsalt | B175: tsk | C175: Chicken salt | D175: tsp | E175: =MATCH(A175,Kalorilista!A:A,0) -> #N/A
A176: Kyndel | B176: tsk | C176: Savory | D176: tsp | E176: =MATCH(A176,Kalorilista!A:A,0) -> #N/A
A177: Lagerblad | B177: st | C177: Bay leaves | D177: pc | E177: =MATCH(A177,Kalorilista!A:A,0) -> #N/A
A178: Lammcurry masala | B178: g | C178: Lamb curry masala | D178: g | E178: =MATCH(A178,Kalorilista!A:A,0) -> #N/A
A179: Lammkorv | B179: st | C179: Lamb sausage | D179: pc | E179: =MATCH(A179,Kalorilista!A:A,0) -> #N/A
A180: Lammkotletter | B180: st | C180: Lamb chop | D180: pc | E180: =MATCH(A180,Kalorilista!A:A,0) -> #N/A
A181: Lammkött | B181: g | C181: Lamb | D181: g | E181: =MATCH(A181,Kalorilista!A:A,0) -> #N/A
A182: Larbkrydda | B182: g | C182: Larb spice | D182: g | E182: =MATCH(A182,Kalorilista!A:A,0) -> #N/A
A183: Lasagneplattor | B183: st | C183: Lasagne plates | D183: pc | E183: =MATCH(A183,Kalorilista!A:A,0) -> #N/A
A184: Lättfil | B184: dl | C184: Light buttermilk | D184: dl | E184: =MATCH(A184,Kalorilista!A:A,0) -> #N/A
A185: Lax | B185: g | C185: Salmon | D185: g | E185: =MATCH(A185,Kalorilista!A:A,0) -> 305
...

Sheet Receptkategorier
A1: Asiatiskt
A2: Bröd
A3: Efterrätter
A4: Fisk
A5: Fläskfilé
A6: Förrätter
A7: Grytor
A8: Italienskt
A9: Jul
A10: Kryddor
A11: Kyckling
A12: Kött
... A32: Svensk husman

Sheet Måttenhet
A1: ark | B1: ark | C1: sheet
A2: burk | B2: burk | C2: jar
A3: cl | B3: centiliter | C3: cl
A4: cm | B4: centimeter | C4: cm
A5: dl | B5: deciliter | C5: dl
A6: flaska | B6: flaska | C6: bottle
A7: fpk | B7: förpackning | C7: pack
A8: g | B8: gram | C8: g
A9: hg | B9: hektogram | C9: hg
A10: kg | B10: kilo | C10: kg
A11: klyfta | B11: klyfta | C11: clove | D11: wedge
A12: knippe | B12: knippe | C12: bunch
A13: krm | B13: kryddmått | C13: pinch
A14: kruka | B14: kruka | C14: pot
A15: kvist | B15: kvist | C15: sprig
A16: l | B16: liter | C16: l
A17: låda | B17: låda | C17: box
A18: limpa | B18: limpa | C18: loaf
A19: mg | B19: milligram | C19: mg
A20: ml | B20: milliliter | C20: ml
A21: msk | B21: matsked | C21: tbsp
A22: nypa | B22: nypa | C22: pinch
A23: paket | B23: paket | C23: packet
... A30: tub | B30: tum | C30: tube

Sheet Nya maträtter
A1: Tavë kosi | B1: Matfilen | F1: Tavë kosi | G1: Matfilen
A2: Carbonnade flamande | F2: Carbonnade flamande
A3: Kanda | F3: Kanda
A4: Empanadas de horno | F4: Empanadas de horno
A5: Kofta | F5: Kofta
A6: Saganaki | F6: Saganaki
A7: Taramosalata | F7: Taramosalata
A8: Poulet à la haïtienne | F8: Poulet à la haïtienne
A9: Baleadas | F9: Baleadas
A10: Jerk chicken | F10: Jerk chicken
A11: Tonkatsusås | F11: Tonkatsusås
A12: Somlar kari saek mouan | F12: Somlar kari saek mouan
A13: Dumplings | F13: Dumplings
... A18: Pommes duchesse | F18: Pommes duchesse

Sheet Kalorilista
B1: Omräkningsfaktor
A2: Namn | B2: Mängd | C2: Enhet | D2: Vikt (g) | E2: kcal/100g
A3: Böngroddar | E3: 0
A4: Havssalt | E4: 0
A5: Mineralvatten | E5: 0
A6: Salt | E6: 0
A7: Salt | E7: 0
A8: Sambal oelek | E8: 0
A9: Sodavatten | E9: 0
A10: Sriracha | E10: 0
A11: Vatten | E11: 0
A12: Kaffe | E12: 2
A13: Fiskbuljong | E13: 4.2
A14: Hönsbuljong | E14: 4.7
... A348: Färs - fläsk fett 20 % | E348: 241.9
A349: Punsch 26 vol. % | B349: 3 | C349: cl | D349: 30 | E349: 244.3
A350: Messmör fett 2 % | E350: 245.2
A351: Grillkorv fett ca 18 % | E351: 245.9
A352: Frukt torkad | E352: 249.4
A353: Fläskkorv rå fett ca 23 % | E353: 249.9
A354: Isterband fett ca19 % | E354: 255.6
A355: Wonton wrappers | E355: 256
A356: Falukorv fett 23 % | E356: 256.6
A357: Wienerkorv fett 23 % | E357: 257
A358: Hönskött m skinn | E358: 261.7
A359: Majonnäs fett 26 % | E359: 264
A360: Grädde fett 27 % | E360: 264.2
A361: Vinbärsgelé svart | E361: 265.7
... A381: Röda bönor | E381: 297.7
A382: Tortilla | B382: 1 | C382: st | D382: 40 | E382: 297.8
A383: Leverpastej skivbar fett ca 26 % | E383: 299
A384: Russin | E384: 299
A385: Linser | E385: 303.4
A386: Nypon - torkade | E386: 303.7
A387: Grahamsmjöl | E387: 309.3
A388: Matjessill | E388: 314
A389: Croissant | B389: 1 | C389: st | D389: 65 | E389: 314.6
A390: Matfett fett 35 | E390: 317.6
A391: Mjöl - råg | E391: 318.7
A392: Mjöl - vete | E392: 318.7
...
